2025-02-26 11:11:46,955 - core.database - INFO - База данных monitoring.db инициализирована
2025-02-26 11:11:46,962 - PerimeterMonitoring - INFO - Инициализация системы мониторинга периметра
 * Serving Flask app 'dashboard.app'
 * Debug mode: off
2025-02-26 11:11:46,967 - modules.security_headers - ERROR - Ошибка при загрузке критических заголовков: module 'config' has no attribute 'get'
2025-02-26 11:11:46,967 - modules.security_headers - ERROR - Ошибка при загрузке рекомендуемых заголовков: module 'config' has no attribute 'get'
2025-02-26 11:11:46,967 - modules.security_headers - ERROR - Ошибка при загрузке ожидаемых значений заголовков: module 'config' has no attribute 'get'
2025-02-26 11:11:46,967 - PerimeterMonitoring - INFO - Система мониторинга инициализирована
2025-02-26 11:11:46,967 - PerimeterMonitoring - INFO - Запуск системы мониторинга периметра
2025-02-26 11:11:46,968 - core.database - INFO - База данных monitoring.db инициализирована
2025-02-26 11:11:46,968 - PerimeterMonitoring - INFO - Запуск полного цикла проверок
2025-02-26 11:11:46,968 - PerimeterMonitoring - INFO - Запуск сканирования IP-адресов
2025-02-26 11:11:46,968 - IPScanner - INFO - Запуск сканирования 1 IP-адресов
2025-02-26 11:11:46,977 - IPScanner - ERROR - Ошибка при выполнении ping до 127.0.0.1: [Errno 2] No such file or directory: 'ping'
2025-02-26 11:11:46,978 - core.database - ERROR - Ошибка при сохранении состояния IP 127.0.0.1: Object of type datetime is not JSON serializable
2025-02-26 11:11:46,978 - IPScanner - INFO - Сканирование завершено. Обнаружено 0 изменений.
2025-02-26 11:11:46,978 - PerimeterMonitoring - INFO - Сканирование IP-адресов завершено: 0 изменений обнаружено
2025-02-26 11:11:46,978 - PerimeterMonitoring - INFO - Запуск проверки доступности веб-сайтов
2025-02-26 11:11:46,978 - WebsiteMonitor - INFO - Запуск проверки 1 веб-сайтов
2025-02-26 11:11:46,980 - werkzeug - INFO - WARNING: This is a development server. Do not use it in a production deployment. Use a production WSGI server instead.
 * Running on all addresses (0.0.0.0)
 * Running on http://127.0.0.1:5000
 * Running on http://172.31.128.9:5000
2025-02-26 11:11:46,980 - werkzeug - INFO - Press CTRL+C to quit
2025-02-26 11:11:47,035 - core.database - ERROR - Ошибка при сохранении состояния сайта http://example.com: Object of type datetime is not JSON serializable
2025-02-26 11:11:47,035 - WebsiteMonitor - INFO - Проверка веб-сайтов завершена. 0 сайтов недоступно. Обнаружено 0 изменений статуса.
2025-02-26 11:11:47,035 - PerimeterMonitoring - INFO - Проверка веб-сайтов завершена: 0 сайтов недоступно
2025-02-26 11:11:47,035 - PerimeterMonitoring - INFO - Запуск проверки SSL-сертификатов
2025-02-26 11:11:47,035 - CertificateChecker - INFO - Запуск проверки SSL-сертификатов для 1 доменов
2025-02-26 11:11:47,216 - core.database - ERROR - Ошибка при сохранении информации о сертификате example.com: Object of type datetime is not JSON serializable
2025-02-26 11:11:47,216 - CertificateChecker - INFO - Проверка сертификатов завершена. 0 сертификатов скоро истекают, 0 ошибок.
2025-02-26 11:11:47,216 - PerimeterMonitoring - INFO - Проверка сертификатов завершена: 0 сертификатов скоро истекают
2025-02-26 11:11:47,216 - PerimeterMonitoring - INFO - Запуск сканирования портов
2025-02-26 11:11:47,216 - PerimeterMonitoring - ERROR - Ошибка при сканировании портов: 'PortScanner' object has no attribute 'scan'
2025-02-26 11:11:47,216 - PerimeterMonitoring - INFO - Запуск проверки DNS-записей
2025-02-26 11:11:47,217 - PerimeterMonitoring - ERROR - Ошибка при проверке DNS-записей: 'DNSMonitor' object has no attribute 'check_all'
2025-02-26 11:11:47,217 - PerimeterMonitoring - INFO - Запуск проверки заголовков безопасности
2025-02-26 11:11:47,217 - PerimeterMonitoring - ERROR - Ошибка при проверке заголовков безопасности: 'SecurityHeadersChecker' object has no attribute 'check_all'
2025-02-26 11:11:47,217 - PerimeterMonitoring - INFO - Полный цикл проверок завершен
2025-02-26 11:11:47,217 - PerimeterMonitoring - INFO - Настройка расписания проверок
2025-02-26 11:11:47,217 - PerimeterMonitoring - INFO - Расписание проверок настроено
2025-02-26 11:11:47,311 - dashboard.app - ERROR - Exception on / [GET]
Traceback (most recent call last):
  File "/home/runner/workspace/.pythonlibs/lib/python3.12/site-packages/flask/app.py", line 2190, in wsgi_app
    response = self.full_dispatch_request()
               ^^^^^^^^^^^^^^^^^^^^^^^^^^^^
  File "/home/runner/workspace/.pythonlibs/lib/python3.12/site-packages/flask/app.py", line 1486, in full_dispatch_request
    rv = self.handle_user_exception(e)
         ^^^^^^^^^^^^^^^^^^^^^^^^^^^^^
  File "/home/runner/workspace/.pythonlibs/lib/python3.12/site-packages/flask/app.py", line 1484, in full_dispatch_request
    rv = self.dispatch_request()
         ^^^^^^^^^^^^^^^^^^^^^^^
  File "/home/runner/workspace/.pythonlibs/lib/python3.12/site-packages/flask/app.py", line 1469, in dispatch_request
    return self.ensure_sync(self.view_functions[rule.endpoint])(**view_args)
           ^^^^^^^^^^^^^^^^^^^^^^^^^^^^^^^^^^^^^^^^^^^^^^^^^^^^^^^^^^^^^^^^^
  File "/home/runner/workspace/dashboard/app.py", line 36, in index
    return render_template('index.html',
          ^^^^^^^^^^^^^^^^^^^^^^^^^^^^^
  File "/home/runner/workspace/.pythonlibs/lib/python3.12/site-packages/flask/templating.py", line 151, in render_template
    return _render(app, template, context)
           ^^^^^^^^^^^^^^^^^^^^^^^^^^^^^^^
  File "/home/runner/workspace/.pythonlibs/lib/python3.12/site-packages/flask/templating.py", line 132, in _render
    rv = template.render(context)
         ^^^^^^^^^^^^^^^^^^^^^^^^
  File "/home/runner/workspace/.pythonlibs/lib/python3.12/site-packages/jinja2/environment.py", line 1295, in render
    self.environment.handle_exception()
  File "/home/runner/workspace/.pythonlibs/lib/python3.12/site-packages/jinja2/environment.py", line 942, in handle_exception
    raise rewrite_traceback_stack(source=source)
  File "/home/runner/workspace/dashboard/templates/index.html", line 1, in top-level template code
    {% extends "base.html" %}
  File "/home/runner/workspace/dashboard/templates/base.html", line 85, in top-level template code
    {% block content %}{% endblock %}
    ^^^^^^^^^^^^^^^^^^^^^^^^^
  File "/home/runner/workspace/dashboard/templates/index.html", line 89, in block 'content'
    <a href="{{ url_for('alerts_page') }}" class="btn btn-outline-primary">Все инциденты</a>
    ^^^^^^^^^^^^^^^^^^^^^^^^^
  File "/home/runner/workspace/.pythonlibs/lib/python3.12/site-packages/flask/app.py", line 1697, in url_for
    return self.handle_url_build_error(error, endpoint, values)
           ^^^^^^^^^^^^^^^^^^^^^^^^^^^^^^^^^^^^^^^^^^^^^^^^^^^^
  File "/home/runner/workspace/.pythonlibs/lib/python3.12/site-packages/flask/app.py", line 1686, in url_for
    rv = url_adapter.build(  # type: ignore[union-attr]
         ^^^^^^^^^^^^^^^^^^^^^^^^^^^^^^^^^^^^^^^^^^^^^^
  File "/home/runner/workspace/.pythonlibs/lib/python3.12/site-packages/werkzeug/routing/map.py", line 924, in build
    raise BuildError(endpoint, values, method, self)
werkzeug.routing.exceptions.BuildError: Could not build url for endpoint 'alerts_page'. Did you mean 'certificates' instead?
2025-02-26 11:11:47,319 - werkzeug - INFO - 172.31.128.9 - - [26/Feb/2025 11:11:47] "GET /?initialPath=/&id=:rkt: HTTP/1.1" 500 -
2025-02-26 11:11:47,351 - dashboard.app - ERROR - Exception on / [GET]
Traceback (most recent call last):
  File "/home/runner/workspace/.pythonlibs/lib/python3.12/site-packages/flask/app.py", line 2190, in wsgi_app
    response = self.full_dispatch_request()
               ^^^^^^^^^^^^^^^^^^^^^^^^^^^^
  File "/home/runner/workspace/.pythonlibs/lib/python3.12/site-packages/flask/app.py", line 1486, in full_dispatch_request
    rv = self.handle_user_exception(e)
         ^^^^^^^^^^^^^^^^^^^^^^^^^^^^^
  File "/home/runner/workspace/.pythonlibs/lib/python3.12/site-packages/flask/app.py", line 1484, in full_dispatch_request
    rv = self.dispatch_request()
         ^^^^^^^^^^^^^^^^^^^^^^^
  File "/home/runner/workspace/.pythonlibs/lib/python3.12/site-packages/flask/app.py", line 1469, in dispatch_request
    return self.ensure_sync(self.view_functions[rule.endpoint])(**view_args)
           ^^^^^^^^^^^^^^^^^^^^^^^^^^^^^^^^^^^^^^^^^^^^^^^^^^^^^^^^^^^^^^^^^
  File "/home/runner/workspace/dashboard/app.py", line 36, in index
    return render_template('index.html',
          ^^^^^^^^^^^^^^^^^^^^^^^^^^^^^
  File "/home/runner/workspace/.pythonlibs/lib/python3.12/site-packages/flask/templating.py", line 151, in render_template
    return _render(app, template, context)
           ^^^^^^^^^^^^^^^^^^^^^^^^^^^^^^^
  File "/home/runner/workspace/.pythonlibs/lib/python3.12/site-packages/flask/templating.py", line 132, in _render
    rv = template.render(context)
         ^^^^^^^^^^^^^^^^^^^^^^^^
  File "/home/runner/workspace/.pythonlibs/lib/python3.12/site-packages/jinja2/environment.py", line 1295, in render
    self.environment.handle_exception()
  File "/home/runner/workspace/.pythonlibs/lib/python3.12/site-packages/jinja2/environment.py", line 942, in handle_exception
    raise rewrite_traceback_stack(source=source)
  File "/home/runner/workspace/dashboard/templates/index.html", line 1, in top-level template code
    {% extends "base.html" %}
  File "/home/runner/workspace/dashboard/templates/base.html", line 85, in top-level template code
    {% block content %}{% endblock %}
    ^^^^^^^^^^^^^^^^^^^^^^^^^
  File "/home/runner/workspace/dashboard/templates/index.html", line 89, in block 'content'
    <a href="{{ url_for('alerts_page') }}" class="btn btn-outline-primary">Все инциденты</a>
    ^^^^^^^^^^^^^^^^^^^^^^^^^
  File "/home/runner/workspace/.pythonlibs/lib/python3.12/site-packages/flask/app.py", line 1697, in url_for
    return self.handle_url_build_error(error, endpoint, values)
           ^^^^^^^^^^^^^^^^^^^^^^^^^^^^^^^^^^^^^^^^^^^^^^^^^^^^
  File "/home/runner/workspace/.pythonlibs/lib/python3.12/site-packages/flask/app.py", line 1686, in url_for
    rv = url_adapter.build(  # type: ignore[union-attr]
         ^^^^^^^^^^^^^^^^^^^^^^^^^^^^^^^^^^^^^^^^^^^^^^
  File "/home/runner/workspace/.pythonlibs/lib/python3.12/site-packages/werkzeug/routing/map.py", line 924, in build
    raise BuildError(endpoint, values, method, self)
werkzeug.routing.exceptions.BuildError: Could not build url for endpoint 'alerts_page'. Did you mean 'certificates' instead?
2025-02-26 11:11:47,354 - werkzeug - INFO - 172.31.128.9 - - [26/Feb/2025 11:11:47] "GET / HTTP/1.1" 500 -
2025-02-26 11:11:47,510 - werkzeug - INFO - 172.31.128.9 - - [26/Feb/2025 11:11:47] "GET /static/css/style.css HTTP/1.1" 404 -
2025-02-26 11:11:47,512 - werkzeug - INFO - 172.31.128.9 - - [26/Feb/2025 11:11:47] "GET /static/js/main.js HTTP/1.1" 404 -
2025-02-26 11:11:47,541 - werkzeug - INFO - 172.31.128.9 - - [26/Feb/2025 11:11:47] "GET /static/css/style.css HTTP/1.1" 404 -
2025-02-26 11:11:47,954 - werkzeug - INFO - 172.31.128.9 - - [26/Feb/2025 11:11:47] "GET /static/js/main.js HTTP/1.1" 404 -
